<?xml version="1.0"?>
<robot name="pincher_x100">
    <link name="pincher_x100_base_link">
        <inertial>
            <mass value="0.1"/>
            <!-- origin rpy="0 0 0" xyz="0.0 0.0 0.0"/ -->
            <inertia ixx="0.1" iyy="0.1" izz="0.1" ixy="0.0" ixz="0.0" iyz="0.0"/>
        </inertial>
        <collision name="collision">
            <origin rpy="0.000000 -0.000000 1.5707963267948966" xyz="0.000000 0.000000 0.000000"/>
            <geometry>
                <mesh filename="package://pincher_x100_description/meshes/PXA-100-A-1-Base.stl" scale="0.001 0.001 0.001"/>
            </geometry>
        </collision>
        <visual name="visual">
            <origin rpy="0.000000 -0.000000 1.5707963267948966" xyz="0.000000 0.000000 0.000000"/>
            <geometry>
                <mesh filename="package://pincher_x100_description/meshes/PXA-100-A-1-Base.stl" scale="0.001 0.001 0.001"/>
            </geometry>
            <material name="pincher_black">
                <color rgba="0.15000 0.150000 0.150000 1.000000"/>
            </material>
        </visual>
    </link>
    <joint name="shoulder_yaw_joint" type="revolute">
        <parent link="pincher_x100_base_link"/>
        <child link="shoulder_yaw_link"/>
        <axis xyz="0.000000 0.000000 1.000000"/>
        <!-- [-180,+180] max_trq:=1.5[Nm] max_vel:=6.35[rad/s] -->
        <limit effort="15" velocity="6.35" lower="-3.141592653589793" upper="+3.141592653589793"/>
        <origin rpy="0.000000 0.000000 0.000000" xyz="0.0 0.0 0.050"/>
    </joint>
    <link name="shoulder_yaw_link">
        <inertial>
            <mass value="0.1"/>
            <!-- origin rpy="0 0 0" xyz="0.0 0.0 0.0"/ -->
            <inertia ixx="0.1" iyy="0.1" izz="0.1" ixy="0.0" ixz="0.0" iyz="0.0"/>
        </inertial>
        <collision name="collision">
            <origin rpy="0.000000 -0.000000 1.5707963267948966" xyz="0.000000 0.000000 0.000000"/>
            <geometry>
                <mesh filename="package://pincher_x100_description/meshes/PXA-100-A-2-Shoulder.stl" scale="0.001 0.001 0.001"/>
            </geometry>
        </collision>
        <visual name="visual">
            <origin rpy="0.000000 -0.000000 1.5707963267948966" xyz="0.000000 0.000000 0.000000"/>
            <geometry>
                <mesh filename="package://pincher_x100_description/meshes/PXA-100-A-2-Shoulder.stl" scale="0.001 0.001 0.001"/>
            </geometry>
            <material name="pincher_black" />
        </visual>
    </link>
    <joint name="shoulder_pitch_joint" type="revolute">
        <parent link="shoulder_yaw_link"/>
        <child link="shoulder_pitch_link"/>
        <axis xyz="0.000000 1.000000 0.000000"/>
        <!-- [-96,+115] max_trq:=1.5[Nm] max_vel:=6.35[rad/s] -->
        <limit effort="15" velocity="6.35" lower="-1.6755160819145565" upper="2.007128639793479"/>
        <!-- origin rpy="0.000000 0.000000 0.000000" xyz="0.0 0.0 0.03945"/-->
        <origin rpy="0.000000 0.000000 0.000000" xyz="0.0 0.0 0.0430"/>
    </joint>
    <link name="shoulder_pitch_link">
        <inertial>
            <mass value="0.1"/>
            <!-- origin rpy="0 0 0" xyz="0.0 0.0 0.0"/ -->
            <inertia ixx="0.1" iyy="0.1" izz="0.1" ixy="0.0" ixz="0.0" iyz="0.0"/>
        </inertial>
        <collision name="collision">
            <origin rpy="0.000000 -0.000000 1.5707963267948966" xyz="0.000000 0.000000 0.000000"/>
            <geometry>
                <mesh filename="package://pincher_x100_description/meshes/PXA-100-A-3-UA.stl" scale="0.001 0.001 0.001"/>
            </geometry>
        </collision>
        <visual name="visual">
            <origin rpy="0.000000 -0.000000 1.5707963267948966" xyz="0.000000 0.000000 0.000000"/>
            <geometry>
                <mesh filename="package://pincher_x100_description/meshes/PXA-100-A-3-UA.stl" scale="0.001 0.001 0.001"/>
            </geometry>
            <material name="pincher_black" />
        </visual>
    </link>
    <joint name="elbow_pitch_joint" type="revolute">
        <parent link="shoulder_pitch_link"/>
        <child link="elbow_pitch_link"/>
        <axis xyz="0.000000 1.000000 0.000000"/>
        <!-- [-120,+90] max_trq:=1.5[Nm] max_vel:=6.35[rad/s] -->
        <limit effort="15" velocity="6.35" lower="-2.0943951023931953" upper="1.5707963267948966"/>
        <origin rpy="0.000000 0.000000 0.000000" xyz="0.035 0.0 0.100"/>
    </joint>
    <link name="elbow_pitch_link">
        <inertial>
            <mass value="0.1"/>
            <!-- origin rpy="0 0 0" xyz="0.0 0.0 0.0"/ -->
            <inertia ixx="0.1" iyy="0.1" izz="0.1" ixy="0.0" ixz="0.0" iyz="0.0"/>
        </inertial>
        <collision name="collision">
            <origin rpy="0.000000 -0.000000 1.5707963267948966" xyz="0.000000 0.000000 0.000000"/>
            <geometry>
                <mesh filename="package://pincher_x100_description/meshes/PXA-100-A-4-Forearm.stl" scale="0.001 0.001 0.001"/>
            </geometry>
        </collision>
        <visual name="visual">
            <origin rpy="0.000000 -0.000000 1.5707963267948966" xyz="0.000000 0.000000 0.000000"/>
            <geometry>
                <mesh filename="package://pincher_x100_description/meshes/PXA-100-A-4-Forearm.stl" scale="0.001 0.001 0.001"/>
            </geometry>
            <material name="pincher_black" />
        </visual>
    </link>
    <joint name="wrist_pitch_joint" type="revolute">
        <parent link="elbow_pitch_link"/>
        <child link="wrist_pitch_link"/>
        <axis xyz="0.000000 1.000000 0.000000"/>
        <!-- [-110,+130] max_trq:=1.5[Nm] max_vel:=6.35[rad/s] -->
        <limit effort="15" velocity="6.35" lower="-1.9198621771937625" upper="2.2689280275926285"/>
        <origin rpy="0.000000 0.000000 0.000000" xyz="0.100 0.0 0.0"/>
    </joint>
    <link name="wrist_pitch_link">
        <inertial>
            <mass value="0.1"/>
            <!-- origin rpy="0 0 0" xyz="0.0 0.0 0.0"/ -->
            <inertia ixx="0.1" iyy="0.1" izz="0.1" ixy="0.0" ixz="0.0" iyz="0.0"/>
        </inertial>
        <collision name="collision">
            <origin rpy="0.000000 -0.000000 1.5707963267948966" xyz="0.000000 0.000000 0.000000"/>
            <geometry>
                <mesh filename="package://pincher_x100_description/meshes/px100_srg.stl" scale="0.001 0.001 0.001"/>
            </geometry>
        </collision>
        <visual name="visual">
            <origin rpy="0.000000 -0.000000 1.5707963267948966" xyz="0.000000 0.000000 0.000000"/>
            <geometry>
                <mesh filename="package://pincher_x100_description/meshes/px100_srg.stl" scale="0.001 0.001 0.001"/>
            </geometry>
            <material name="pincher_black" />
        </visual>
    </link>
    <joint name="wrist_roll_joint" type="revolute">
        <parent link="wrist_pitch_link"/>
        <child link="wrist_roll_link"/>
        <axis xyz="1.000000 0.000000 0.000000"/>
        <!-- [-180,+180] max_trq:=1.5[Nm] max_vel:=6.35[rad/s] -->
        <limit effort="15" velocity="6.35" lower="-3.1415" upper="3.1415"/>
        <origin rpy="0.000000 0.000000 0.000000" xyz="0.0655 0.0 0.0"/>
    </joint>
    <link name="wrist_roll_link">
        <inertial>
            <mass value="0.1"/>
            <!-- origin rpy="0 0 0" xyz="0.0 0.0 0.0"/ -->
            <inertia ixx="0.1" iyy="0.1" izz="0.1" ixy="0.0" ixz="0.0" iyz="0.0"/>
        </inertial>
        <collision name="collision1">
            <origin rpy="1.5707963267948966 0.000000 1.5707963267948966" xyz="0.003 0.000000 0.000000"/>
            <geometry>
                <mesh filename="package://pincher_x100_description/meshes/camera_d435_mount2.stl" scale="0.001 0.001 0.001"/>
            </geometry>
            <material name="pincher_black" />
        </collision>
        <collision name="collision2">
            <origin rpy="1.5707963267948966 0.000000 1.5707963267948966" xyz="0.006 0.000000 0.000000"/>
            <geometry>
                <mesh filename="package://pincher_x100_description/meshes/camera_d435_mount.stl" scale="0.001 0.001 0.001"/>
            </geometry>
            <material name="pincher_black" />
        </collision>
        <!--
        <collision name="collision">
            <origin rpy="1.5707963267948966 0.0 1.5707963267948966" xyz="0.03105 0.000000 0.000000"/>
            <geometry>
                <mesh filename="package://realsense2_camera/meshes/d435.dae" scale="1 1 1"/>
            </geometry>
        </collision>
        -->
        <visual name="visual1">
            <origin rpy="1.5707963267948966 0.000000 1.5707963267948966" xyz="0.003 0.000000 0.000000"/>
            <geometry>
                <mesh filename="package://pincher_x100_description/meshes/camera_d435_mount2.stl" scale="0.001 0.001 0.001"/>
            </geometry>
            <material name="pincher_black" />
        </visual>
        <visual name="visual2">
            <origin rpy="1.5707963267948966 0.000000 1.5707963267948966" xyz="0.006 0.000000 0.000000"/>
            <geometry>
                <mesh filename="package://pincher_x100_description/meshes/camera_d435_mount.stl" scale="0.001 0.001 0.001"/>
            </geometry>
            <material name="pincher_black" />
        </visual>
        <!--
        <visual name="visual3">
            <!- - x = 0.02505 + 0.006 - ->
            <origin rpy="1.5707963267948966 0.0 1.5707963267948966" xyz="0.03105 0.000000 0.000000"/>
            <geometry>
                <mesh filename="package://realsense2_camera/meshes/d435.dae" scale="1 1 1"/>
            </geometry>
            <material name="pincher_black" />
        </visual>
        -->
    </link>
    <joint name="wrist_depth_optical_frame_joint" type="fixed">
        <parent link="wrist_roll_link"/>
        <child link="wrist_depth_optical_frame"/>
        <origin rpy="-1.5707963267948966 0.000000 -1.5707963267948966" xyz="0.0 0.0 0.0"/>
    </joint>
    <link name="wrist_depth_optical_frame" />
</robot>
